Workbook
Name Slicer_Region: #N/A
Name Slicer_State: #N/A

Sheet Original-Structure Data
A1: State | B1: 2001- 02 | C1: 2002- 03 | D1: 2003- 04 | E1: 2004- 05 | F1: 2005- 06 | G1: 2006- 07 | H1: 2007- 08 | I1: 2008- 09 | J1: 2009- 10 | K1: 2010- 11 | L1: 2011- 12 | M1: 2012- 13 | N1: 2013- 14 | O1: 2014- 15 | P1: 2015- 16 | Q1: 2016- 17 | R1: 2017-18 | S1: 2018-19 | T1: 2019-20 | U1: 2020-21 | V1: 2021-22 | W1: 2022- 23 | X1: 2023- 24 | Y1: Total | Z1: Region | AA1: Total Increase | AB1: Column1
A2: Bihar | B2: 2664 | C2: 2869 | D2: 3180 | E2: 4743 | F2: 5060 | G2: 5451 | H2: 5783 | I2: 5934 | J2: 6124 | K2: 6517 | L2: 6643 | M2: 6845 | N2: 7197 | O2: 7775 | P2: 8288 | Q2: 8711 | R2: 9242 | S2: 9818 | T2: 10480 | U2: 11502 | V2: 12253 | W2: 12503 | X2: 12853 | Y2: 172435 | Z2: East India | AA2: 3.8246997 | AB2: 3.82
A3: Rajasthan | B3: 7758 | C3: 7789 | D3: 8054 | E3: 8310 | F3: 8713 | G3: 10309 | H3: 11377 | I3: 11931 | J3: 12330 | K3: 13234 | L3: 13512 | M3: 13946 | N3: 14573 | O3: 16934 | P3: 18500 | Q3: 20850 | R3: 22427 | S3: 23668 | T3: 25573 | U3: 30723 | V3: 33265 | W3: 33307 | X3: 34733 | Y3: 401816 | Z3: North India | AA3: 3.4770559 | AB3: 3.48
A4: Madhya Pradesh | B4: 5283 | C4: 5343 | D4: 5388 | E4: 5506 | F4: 6283 | G4: 6374 | H4: 6572 | I4: 6855 | J4: 7167 | K4: 7514 | L4: 8149 | M4: 8838 | N4: 9599 | O4: 10779 | P4: 12148 | Q4: 13445 | R4: 14713 | S4: 15911 | T4: 17109 | U4: 17999 | V4: 19004 | W4: 20122 | X4: 21326 | Y4: 251427 | Z4: Central India | AA4: 3.0367216 | AB4: 3.04
A5: Jharkhand | B5: 940 | C5: 952 | D5: 954 | E5: 1330 | F5: 1335 | G5: 1401 | H5: 1442 | I5: 1466 | J5: 1463 | K5: 1555 | L5: 1745 | M5: 1679 | N5: 1700 | O5: 1734 | P5: 1812 | Q5: 1894 | R5: 2016 | S5: 2183 | T5: 2321 | U5: 2434 | V5: 2629 | W5: 2774 | X5: 3025 | Y5: 40784 | Z5: East India | AA5: 2.2180851 | AB5: 2.22
A6: Gujarat | B6: 5862 | C6: 6089 | D6: 6421 | E6: 6745 | F6: 6960 | G6: 7533 | H6: 7911 | I6: 8386 | J6: 8844 | K6: 9321 | L6: 9817 | M6: 10315 | N6: 11112 | O6: 11691 | P6: 12262 | Q6: 12784 | R6: 13569 | S6: 14493 | T6: 15292 | U6: 15853 | V6: 16722 | W6: 17281 | X6: 18312 | Y6: 253575 | Z6: West India | AA6: 2.1238485 | AB6: 2.12
A7: Ladakh | B7: 0 | C7: 0 | D7: 0 | E7: 0 | F7: 0 | G7: 0 | H7: 0 | I7: 0 | J7: 0 | K7: 0 | L7: 0 | M7: 0 | N7: 0 | O7: 0 | P7: 0 | Q7: 0 | R7: 0 | S7: 0 | T7: 0 | U7: 15 | V7: 29 | W7: 31 | X7: 29.31 | Y7: 104.31 | Z7: North India | AA7: 2.0666667 | AB7: #DIV/0!
A8: Lakshadweep | B8: 2 | C8: 2 | D8: 1 | E8: 1 | F8: 2 | G8: 2 | H8: 2 | I8: 2 | J8: 2 | K8: 2 | L8: 2 | M8: 2 | N8: 6 | O8: 4 | P8: 3 | Q8: 3 | R8: 3 | S8: 4 | T8: 4 | U8: 4 | V8: 0.42 | W8: 0.41 | X8: 0.39 | Y8: 54.22 | Z8: Island Territories | AA8: 2 | AB8: -0.81
A9: Odisha | B9: 929 | C9: 941 | D9: 997 | E9: 1283 | F9: 1342 | G9: 1431 | H9: 1625 | I9: 1598 | J9: 1651 | K9: 1671 | L9: 1721 | M9: 1724 | N9: 1861 | O9: 1903 | P9: 1930 | Q9: 2003 | R9: 2088 | S9: 2311 | T9: 2370 | U9: 2373 | V9: 2402 | W9: 2476 | X9: 2636 | Y9: 41266 | Z9: East India | AA9: 1.8374596 | AB9: 1.84
A10: All India | B10: 84406 | C10: 86159 | D10: 88082 | E10: 92484 | F10: 97066 | G10: 102580 | H10: 107934 | I10: 112183 | J10: 116425 | K10: 121848 | L10: 127904 | M10: 132431 | N10: 137685 | O10: 146314 | P10: 155491 | Q10: 165404 | R10: 176347 | S10: 187749 | T10: 198440 | U10: 209960 | V10: 222069 | W10: 230577 | X10: 239299 | Y10: 3338837 | AA10: 1.8350947 | AB10: 1.84
A11: Karnataka | B11: 4797 | C11: 4539 | D11: 3857 | E11: 3917 | F11: 4022 | G11: 4124 | H11: 4244 | I11: 4538 | J11: 4822 | K11: 5114 | L11: 5447 | M11: 5718 | N11: 5997 | O11: 6121 | P11: 6344 | Q11: 6562 | R11: 7137 | S11: 7901 | T11: 9031 | U11: 10936 | V11: 11796 | W11: 12829 | X11: 13463 | Y11: 153256 | Z11: South India | AA11: 1.8065458 | AB11: 1.81
A12: Tripura | B12: 90 | C12: 79 | D12: 84 | E12: 86 | F12: 87 | G12: 89 | H12: 91 | I12: 96 | J12: 100 | K12: 104 | L12: 111 | M12: 118 | N12: 130 | O12: 141 | P12: 152 | Q12: 160 | R12: 174 | S12: 185 | T12: 199 | U12: 206 | V12: 217 | W12: 230 | X12: 247 | Y12: 3176 | Z12: North-East India | AA12: 1.7444444 | AB12: 1.74
A13: Chhattisgarh | B13: 795 | C13: 804 | D13: 812 | E13: 831 | F13: 839 | G13: 849 | H13: 866 | I13: 908 | J13: 956 | K13: 1029 | L13: 1119 | M13: 1164 | N13: 1209 | O13: 1232 | P13: 1277 | Q13: 1374 | R13: 1469 | S13: 1567 | T13: 1676 | U13: 1747 | V13: 1848 | W13: 1956 | X13: 2124 | Y13: 28451 | Z13: Central India | AA13: 1.6716981 | AB13: 1.67
A14: Andhra Pradesh | B14: 5814 | C14: 6584 | D14: 6959 | E14: 7257 | F14: 7624 | G14: 7938 | H14: 8925 | I14: 9570 | J14: 10429 | K14: 11203 | L14: 12088 | M14: 12762 | N14: 13007 | O14: 9656 | P14: 10817 | Q14: 12178 | R14: 13725 | S14: 15044 | T14: 15263 | U14: 14714 | V14: 15403 | W14: 15448 | X14: 13994 | Y14: 256402 | Z14: South India | AA14: 1.6570347 | AB14: 1.41
A15: Uttar Pradesh | B15: 14648 | C15: 15288 | D15: 15943 | E15: 16512 | F15: 17356 | G15: 18094 | H15: 18861 | I15: 19537 | J15: 20203 | K15: 21031 | L15: 22556 | M15: 23330 | N15: 24194 | O15: 25198 | P15: 26387 | Q15: 27770 | R15: 29052 | S15: 30519 | T15: 31864 | U15: 31359 | V15: 33874 | W15: 36242 | X15: 38780 | Y15: 558598 | Z15: North India | AA15: 1.6474604 | AB15: 1.65
A16: Maharashtra | B16: 6094 | C16: 6238 | D16: 6379 | E16: 6567 | F16: 6769 | G16: 6978 | H16: 7210 | I16: 7455 | J16: 7679 | K16: 8044 | L16: 8469 | M16: 8734 | N16: 9089 | O16: 9542 | P16: 10153 | Q16: 10402 | R16: 11102 | S16: 11655 | T16: 12024 | U16: 13703 | V16: 14305 | W16: 15042 | X16: 16045 | Y16: 219678 | Z16: West India | AA16: 1.6329176 | AB16: 1.63
A17: Haryana | B17: 4978 | C17: 5124 | D17: 5221 | E17: 5222 | F17: 5299 | G17: 5366 | H17: 5442 | I17: 5745 | J17: 6006 | K17: 6267 | L17: 6661 | M17: 7040 | N17: 7442 | O17: 7901 | P17: 8381 | Q17: 8975 | R17: 9809 | S17: 10726 | T17: 11735 | U17: 11284 | V17: 11630 | W17: 11966 | X17: 12220 | Y17: 180440 | Z17: North India | AA17: 1.4548011 | AB17: 1.45
A18: Telangana | B18: 0 | C18: 0 | D18: 0 | E18: 0 | F18: 0 | G18: 0 | H18: 0 | I18: 0 | J18: 0 | K18: 0 | L18: 0 | M18: 0 | N18: 0 | O18: 4207 | P18: 4442 | Q18: 4681 | R18: 4965 | S18: 5416 | T18: 5590 | U18: 5765 | V18: 5808 | W18: 5855 | X18: 5840 | Y18: 52569 | Z18: South India | AA18: 1.3917281 | AB18: #DIV/0!
A19: Sikkim | B19: 37 | C19: 45 | D19: 48 | E19: 46 | F19: 48 | G19: 49 | H19: 42 | I19: 42 | J19: 44 | K19: 43 | L19: 45 | M19: 42 | N19: 46 | O19: 50 | P19: 67 | Q19: 54 | R19: 59 | S19: 61 | T19: 84 | U19: 74 | V19: 87 | W19: 87 | X19: 81 | Y19: 1281 | Z19: North-East India | AA19: 1.3513514 | AB19: 1.19
A20: Himachal Pradesh | B20: 756 | C20: 773 | D20: 786 | E20: 870 | F20: 869 | G20: 933 | H20: 1007 | I20: 1026 | J20: 971 | K20: 1102 | L20: 1120 | M20: 1139 | N20: 1151 | O20: 1172 | P20: 1283 | Q20: 1329 | R20: 1392 | S20: 1460 | T20: 1531 | U20: 1576 | V20: 1615 | W20: 1617 | X20: 1749 | Y20: 27227 | Z20: North India | AA20: 1.3134921 | AB20: 1.31
A21: West Bengal | B21: 3515 | C21: 3600 | D21: 3686 | E21: 3790 | F21: 3891 | G21: 3983 | H21: 4087 | I21: 4176 | J21: 4300 | K21: 4471 | L21: 4672 | M21: 4859 | N21: 4906 | O21: 4961 | P21: 5038 | Q21: 5183 | R21: 5389 | S21: 5607 | T21: 5869 | U21: 6165 | V21: 6414 | W21: 6969 | X21: 7650 | Y21: 113181 | Z21: East India | AA21: 1.1763869 | AB21: 1.18
A22: Tamil Nadu | B22: 4988 | C22: 4622 | D22: 4752 | E22: 4784 | F22: 5474 | G22: 6277 | H22: 6540 | I22: 6651 | J22: 6787 | K22: 6831 | L22: 6968 | M22: 7005 | N22: 7049 | O22: 7132 | P22: 7244 | Q22: 7556 | R22: 7742 | S22: 8362 | T22: 8759 | U22: 9790 | V22: 10107 | W22: 10317 | X22: 10808 | Y22: 166545 | Z22: South India | AA22: 1.1668003 | AB22: 1.17
A23: J & K | B23: 1360 | C23: 1389 | D23: 1414 | E23: 1422 | F23: 1400 | G23: 1400 | H23: 1519 | I23: 1565 | J23: 1592 | K23: 1609 | L23: 1614 | M23: 1631 | N23: 1615 | O23: 1951 | P23: 2273 | Q23: 2376 | R23: 2460 | S23: 2540 | T23: 2506 | U23: 2595 | V23: 2727 | W23: 2817 | X23: 2875 | Y23: 44650 | Z23: North India | AA23: 1.1139706 | AB23: 1.11
A24: Mizoram | B24: 14 | C24: 15 | D24: 15 | E24: 16 | F24: 15 | G24: 16 | H24: 17 | I24: 17 | J24: 11 | K24: 11 | L24: 14 | M24: 14 | N24: 15 | O24: 20 | P24: 22 | Q24: 24 | R24: 25 | S24: 26 | T24: 24 | U24: 25 | V24: 25 | W24: 24 | X24: 25 | Y24: 430 | Z24: North-East India | AA24: 0.85714286 | AB24: 0.79
A25: Punjab | B25: 7932 | C25: 8173 | D25: 8391 | E25: 8554 | F25: 8909 | G25: 9168 | H25: 9282 | I25: 9387 | J25: 9389 | K25: 9423 | L25: 9551 | M25: 9724 | N25: 10011 | O25: 10351 | P25: 10774 | Q25: 11282 | R25: 11855 | S25: 12599 | T25: 13348 | U25: 13394 | V25: 14077 | W25: 14301 | X25: 14000 | Y25: 243875 | Z25: North India | AA25: 0.80295008 | AB25: 0.77
A26: Uttarakhand | B26: 1066 | C26: 1079 | D26: 1188 | E26: 1195 | F26: 1206 | G26: 1213 | H26: 1221 | I26: 1230 | J26: 1377 | K26: 1383 | L26: 1417 | M26: 1478 | N26: 1550 | O26: 1565 | P26: 1656 | Q26: 1692 | R26: 1742 | S26: 1792 | T26: 1845 | U26: 1797 | V26: 1856 | W26: 1859 | X26: 1898 | Y26: 34305 | Z26: North India | AA26: 0.7804878 | AB26: 0.78
A27: Delhi | B27: 294 | C27: 296 | D27: 299 | E27: 303 | F27: 310 | G27: 288 | H27: 445 | I27: 450 | J27: 466 | K27: 480 | L27: 502 | M27: 287 | N27: 284 | O27: 280 | P27: 281 | Q27: 279 | R27: 279 | S27: 300 | T27: 300 | U27: 450 | V27: 450 | W27: 488 | X27: 488 | Y27: 8299 | Z27: North India | AA27: 0.70748299 | AB27: 0.66
A28: Assam | B28: 682 | C28: 705 | D28: 727 | E28: 739 | F28: 747 | G28: 750 | H28: 752 | I28: 753 | J28: 756 | K28: 790 | L28: 796 | M28: 800 | N28: 815 | O28: 829 | P28: 843 | Q28: 861 | R28: 872 | S28: 882 | T28: 920 | U28: 954 | V28: 982 | W28: 1006 | X28: 1092 | Y28: 19053 | Z28: North-East India | AA28: 0.60117302 | AB28: 0.6
A29: Goa | B29: 45 | C29: 46 | D29: 48 | E29: 57 | F29: 56 | G29: 57 | H29: 58 | I29: 59 | J29: 59 | K29: 60 | L29: 60 | M29: 61 | N29: 68 | O29: 67 | P29: 54 | Q29: 51 | R29: 55 | S29: 57 | T29: 61 | U29: 60 | V29: 63 | W29: 64 | X29: 64 | Y29: 1330 | Z29: West India | AA29: 0.51111111 | AB29: 0.42
A30: Meghalaya | B30: 66 | C30: 68 | D30: 69 | E30: 71 | F30: 73 | G30: 74 | H30: 77 | I30: 77 | J30: 78 | K30: 79 | L30: 80 | M30: 81 | N30: 82 | O30: 83 | P30: 84 | Q30: 84 | R30: 85 | S30: 87 | T30: 88 | U30: 89 | V30: 90 | W30: 94 | X30: 97 | Y30: 1856 | Z30: North-East India | AA30: 0.46969697 | AB30: 0.47
... A34: Puducherry | B34: 37 | C34: 37 | D34: 40 | E34: 41 | F34: 43 | G34: 45 | H34: 46 | I34: 46 | J34: 46 | K34: 47 | L34: 45 | M34: 47 | N34: 47 | O34: 48 | P34: 48 | Q34: 48 | R34: 49 | S34: 49 | T34: 50 | U34: 50 | V34: 50 | W34: 50 | X34: 50 | Y34: 1059 | Z34: South India | AA34: 0.35135135 | AB34: 0.35
A35: Chandigarh | B35: 43 | C35: 43 | D35: 44 | E35: 43 | F35: 46 | G35: 46 | H35: 47 | I35: 47 | J35: 46 | K35: 45 | L35: 45 | M35: 44 | N35: 44 | O35: 44 | P35: 43 | Q35: 36 | R35: 42 | S35: 45 | T35: 49 | U35: 52 | V35: 57 | W35: 56 | X35: 58.87 | Y35: 1007 | Z35: North India | AA35: 0.3255814 | AB35: #VALUE!
A36: Manipur | B36: 68 | C36: 69 | D36: 71 | E36: 75 | F36: 77 | G36: 77 | H36: 78 | I36: 78 | J36: 78 | K36: 78 | L36: 79 | M36: 80 | N36: 82 | O36: 82 | P36: 79 | Q36: 79 | R36: 82 | S36: 86 | T36: 90 | U36: 71 | V36: 76 | W36: 72 | X36: 63 | Y36: 1770 | Z36: North-East India | AA36: 0.32352941 | AB36: -0.07
A37: A&N Islands | B37: 23 | C37: 26 | D37: 25 | E37: 24 | F37: 20 | G37: 23 | H37: 24 | I37: 26 | J37: 24 | K37: 25 | L37: 26 | M37: 21 | N37: 14 | O37: 16 | P37: 15 | Q37: 16 | R37: 17 | S37: 18 | T37: 19 | U37: 15 | V37: 17 | W37: 17 | X37: 18 | Y37: 469 | Z37: Island Territories | AA37: 0.13043478 | AB37: -0.22
A38: Kerala | B38: 2718 | C38: 2419 | D38: 2111 | E38: 2025 | F38: 2063 | G38: 2119 | H38: 2253 | I38: 2441 | J38: 2509 | K38: 2645 | L38: 2716 | M38: 2791 | N38: 2655 | O38: 2711 | P38: 2650 | Q38: 2520 | R38: 2576 | S38: 2548 | T38: 2544 | U38: 2534 | V38: 2532 | W38: 2580 | X38: 2580 | Y38: 57240 | Z38: South India | AA38: 0.026857984 | AB38: -0.05
A39: Daman & Diu | B39: 1 | C39: 1 | D39: 1 | E39: 1 | F39: 1 | G39: 1 | H39: 1 | I39: 1 | J39: 1 | K39: 1 | L39: 1 | M39: 1 | N39: 1 | O39: 1 | P39: 0 | Q39: 0 | R39: 0 | S39: 0 | T39: 0 | U39: 0 | V39: 0 | W39: 0 | X39: 0 | Y39: 14 | Z39: West India | AA39: 0 | AB39: -1

Sheet Re-structured Data
A1: Year | B1: State | C1: Region | D1: Milk | E1: Total Growth | F1: 5 Year Rolling
A2: 2001-02 | B2: Andhra Pradesh | C2: South India | D2: 5814 | E2: 1.4069487 | F2: 0 | H2: =IF(Table1[[#This Row],[Year]]="2001-02", (OFFSET(Table1[[#This Row],[Milk]], 22, 0)-Table1[[#This Row],[Milk]])/Table1[[#This Row],[Milk]], 0) -> 1.4069487
A3: 2002-03 | B3: Andhra Pradesh | C3: South India | D3: 6584 | E3: 0 | F3: 0
A4: 2003-04 | B4: Andhra Pradesh | C4: South India | D4: 6959 | E4: 0 | F4: 0
A5: 2004-05 | B5: Andhra Pradesh | C5: South India | D5: 7257 | E5: 0 | F5: 6653.5
A6: 2005-06 | B6: Andhra Pradesh | C6: South India | D6: 7624 | E6: 0 | F6: 6847.6
A7: 2006-07 | B7: Andhra Pradesh | C7: South India | D7: 7938 | E7: 0 | F7: 7272.4
A8: 2007-08 | B8: Andhra Pradesh | C8: South India | D8: 8925 | E8: 0 | F8: 7740.6
A9: 2008-09 | B9: Andhra Pradesh | C9: South India | D9: 9570 | E9: 0 | F9: 8262.8
A10: 2009-10 | B10: Andhra Pradesh | C10: South India | D10: 10429 | E10: 0 | F10: 8897.2
A11: 2010-11 | B11: Andhra Pradesh | C11: South India | D11: 11203 | E11: 0 | F11: 9613
A12: 2011-12 | B12: Andhra Pradesh | C12: South India | D12: 12088 | E12: 0 | F12: 10443
A13: 2012-13 | B13: Andhra Pradesh | C13: South India | D13: 12762 | E13: 0 | F13: 11210.4
A14: 2013-14 | B14: Andhra Pradesh | C14: South India | D14: 13007 | E14: 0 | F14: 11897.8
... A689: 2023-24 | B689: Delhi | C689: North India | D689: 735 | E689: 0 | F689: 707

Sheet Analysis
A1: Total Milk Production By States | H1: Total Milk Production & Growth
V2: Year | W2: 2023-24
A3: Year | B3: 2023-24 | V3: Region | W3: Central India
A4: Region | B4: Central India | C4: =$B$4 -> Central India | O4: Year | P4: 2023-24 | AB4: Year | AC4: 2023-24
H5: Region | I5: (All) | O5: State | P5: (All) | V5: Row Labels | W5: Sum of Milk
A6: Row Labels | B6: Sum of Milk | C6: Rank | H6: State | I6: (All) | O6: Region | P6: Central India | V6: Madhya Pradesh | W6: 21326 | AB6: Row Labels | AC6: Sum of Milk
A7: Madhya Pradesh | B7: 21326 | C7: =IFERROR(RANK(GETPIVOTDATA("Milk",$O$8),B7:B35,0),"-") -> - | V7: Chhattisgarh | W7: 2124 | AB7: North India | AC7: 61120
A8: Chhattisgarh | B8: 2124 | C8: =IF($C$4<>"(All)",$C$7,"-") -> - | H8: Row Labels | I8: Sum of Milk | J8: Sum of Milk2 | O8: Sum of Milk | V8: Grand Total | W8: 23450 | AB8: South India | AC8: 47874
H9: 2001-02 | I9: 87062 | O9: 23450 | AB9: West India | AC9: 34421
H10: 2002-03 | I10: 89541 | J10: 0.028473961 | AB10: East India | AC10: 26767
H11: 2003-04 | I11: 91283 | J11: 0.019454775 | AB11: Central India | AC11: 23450
H12: 2004-05 | I12: 95803 | J12: 0.049516339 | S12: State | T12: (All) | AB12: North East India | AC12: 1634
H13: 2005-06 | I13: 99198 | J13: 0.035437304 | O13: State | P13: (All) | S13: Year | T13: 2023-24 | AB13: Grand Total | AC13: 195266
H14: 2006-07 | I14: 102489 | J14: 0.033176072 | O14: Region | P14: Central India | S14: Region | T14: (All)
H15: 2007-08 | I15: 106605 | J15: 0.040160407
H16: 2008-09 | I16: 110503 | J16: 0.036564889 | O16: Row Labels | P16: Sum of Milk | S16: Sum of Milk
H17: 2009-10 | I17: 114541 | J17: 0.036541994 | O17: 2001-02 | S17: 195266
H18: 2010-11 | I18: 119185 | J18: 0.040544434 | O18: 2002-03 | P18: 0.011352419 | S18: National Share
H19: 2011-12 | I19: 124146 | J19: 0.041624365 | O19: 2003-04 | P19: 0.0086220921 | S19: =GETPIVOTDATA("Milk",$O$8)/GETPIVOTDATA("Milk",$S$16) -> 0.12009259
H20: 2012-13 | I20: 128435 | J20: 0.034548032 | O20: 2004-05 | P20: 0.022096774
H21: 2013-14 | I21: 132962 | J21: 0.035247401 | O21: 2005-06 | P21: 0.12387565
H22: 2014-15 | I22: 134743 | J22: 0.013394805 | O22: 2006-07 | P22: 0.01418141
H23: 2015-16 | I23: 141435 | J23: 0.049664918 | O23: 2007-08 | P23: 0.029766025
H24: 2016-17 | I24: 147632 | J24: 0.04381518 | O24: 2008-09 | P24: 0.043694542
H25: 2017-18 | I25: 155639 | J25: 0.054236209 | O25: 2009-10 | P25: 0.046373825
H26: 2018-19 | I26: 163768 | J26: 0.05222984 | O26: 2010-11 | P26: 0.051705035
H27: 2019-20 | I27: 170789 | J27: 0.042871623 | O27: 2011-12 | P27: 0.084864802
H28: 2020-21 | I28: 177411 | J28: 0.038772989 | O28: 2012-13 | P28: 0.079197238
H29: 2021-22 | I29: 184336.8 | J29: 0.039038166 | O29: 2013-14 | P29: 0.080583883
H30: 2022-23 | I30: 190142 | J30: 0.031492355 | O30: 2014-15 | P30: 0.11130644
H31: 2023-24 | I31: 195266 | J31: 0.026948281 | O31: 2015-16 | P31: 0.11772542 | AA31: Region | AB31: Central India
H32: Grand Total | I32: 3062914.8 | O32: 2016-17 | P32: 0.10383613
O33: 2017-18 | P33: 0.091976517 | AA33: Row Labels | AB33: Total Growth 2001-24
O34: 2018-19 | P34: 0.080088988 | AA34: Chhattisgarh | AB34: 1.6716981
O35: 2019-20 | P35: 0.074779723 | AA35: Madhya Pradesh | AB35: 3.0367216
O36: 2020-21 | P36: 0.051157839 | AA36: Grand Total | AB36: 4.7084197
O37: 2021-22 | P37: 0.056011344
O38: 2022-23 | P38: 0.058795319
O39: 2023-24 | P39: 0.06214331
O40: Grand Total
...

Sheet Dashboard
A1: India Milk Production Analysis 2001-24
F7: Milk Production | I7: Annual Growth % | L7: National Share % | O7: Rank | R7: Regional Analysis
F8: =CONCATENATE(GETPIVOTDATA("Milk",Analysis!$O$8)," MT") -> 23450 MT | I8: =Analysis!P41 -> 0.063824305 | L8: =Analysis!S19 -> 0.12009259 | O8: =Analysis!C7 -> -
F11: Trend Analysis
AG47: Top States | AJ47: Top Regions
AG48: State | AH48: Milk (MT) | AJ48: Region | AK48: Milk (MT)
AG49: =Analysis!A7 -> Madhya Pradesh | AH49: =Analysis!B7 -> 21326 | AJ49: =Analysis!AB7 -> North India | AK49: =Analysis!AC7 -> 61120
AG50: =Analysis!A8 -> Chhattisgarh | AH50: =Analysis!B8 -> 2124 | AJ50: =Analysis!AB8 -> South India | AK50: =Analysis!AC8 -> 47874
AG51: =Analysis!A9 -> 0 | AH51: =Analysis!B9 -> 0 | AJ51: =Analysis!AB9 -> West India | AK51: =Analysis!AC9 -> 34421
AG52: =Analysis!A10 -> 0 | AH52: =Analysis!B10 -> 0 | AJ52: =Analysis!AB10 -> East India | AK52: =Analysis!AC10 -> 26767
AG53: =Analysis!A11 -> 0 | AH53: =Analysis!B11 -> 0 | AJ53: =Analysis!AB11 -> Central India | AK53: =Analysis!AC11 -> 23450
AG54: =Analysis!A12 -> 0 | AH54: =Analysis!B12 -> 0 | AJ54: =Analysis!AB12 -> North East India | AK54: =Analysis!AC12 -> 1634
AG55: =Analysis!A13 -> 0 | AH55: =Analysis!B13 -> 0
AG56: =Analysis!A14 -> 0 | AH56: =Analysis!B14 -> 0
AG57: =Analysis!A15 -> 0 | AH57: =Analysis!B15 -> 0
AG58: =Analysis!A16 -> 0 | AH58: =Analysis!B16 -> 0
