Workbook
Name Slicer_Region: #N/A
Name Slicer_State: #N/A
Name Slicer_Year: #N/A

Sheet Sheet1
A1: State | B1: 2001- 02 | C1: 2002- 03 | D1: 2003- 04 | E1: 2004- 05 | F1: 2005- 06 | G1: 2006- 07 | H1: 2007- 08 | I1: 2008- 09 | J1: 2009- 10 | K1: 2010- 11 | L1: 2011- 12 | M1: 2012- 13 | N1: 2013- 14 | O1: 2014- 15 | P1: 2015- 16 | Q1: 2016- 17 | R1: 2017-18 | S1: 2018-19 | T1: 2019-20 | U1: 2020-21 | V1: 2021-22 | W1: 2022- 23 | X1: 2023- 24 | Y1: Total | Z1: Region | AA1: Total Increase
A2: Andhra Pradesh | B2: 5814 | C2: 6584 | D2: 6959 | E2: 7257 | F2: 7624 | G2: 7938 | H2: 8925 | I2: 9570 | J2: 10429 | K2: 11203 | L2: 12088 | M2: 12762 | N2: 13007 | O2: 9656 | P2: 10817 | Q2: 12178 | R2: 13725 | S2: 15044 | T2: 15263 | U2: 14714 | V2: 15403 | W2: 15448 | X2: 13994 | Y2: 256402 | Z2: South India | AA2: =(MAX(B2:X2)-B2)/B2 -> 1.6570347
A3: Arunachal Pradesh | B3: 42 | C3: 46 | D3: 46 | E3: 48 | F3: 48 | G3: 49 | H3: 32 | I3: 24 | J3: 26 | K3: 28 | L3: 22 | M3: 23 | N3: 43 | O3: 46 | P3: 50 | Q3: 53 | R3: 54 | S3: 55 | T3: 61 | U3: 44 | V3: 46 | W3: 46 | X3: 20 | Y3: 952 | Z3: North-East India | AA3: =(MAX(B3:X3)-B3)/B3 -> 0.45238095
A4: Assam | B4: 682 | C4: 705 | D4: 727 | E4: 739 | F4: 747 | G4: 750 | H4: 752 | I4: 753 | J4: 756 | K4: 790 | L4: 796 | M4: 800 | N4: 815 | O4: 829 | P4: 843 | Q4: 861 | R4: 872 | S4: 882 | T4: 920 | U4: 954 | V4: 982 | W4: 1006 | X4: 1092 | Y4: 19053 | Z4: North-East India | AA4: =(MAX(B4:X4)-B4)/B4 -> 0.60117302
A5: Bihar | B5: 2664 | C5: 2869 | D5: 3180 | E5: 4743 | F5: 5060 | G5: 5451 | H5: 5783 | I5: 5934 | J5: 6124 | K5: 6517 | L5: 6643 | M5: 6845 | N5: 7197 | O5: 7775 | P5: 8288 | Q5: 8711 | R5: 9242 | S5: 9818 | T5: 10480 | U5: 11502 | V5: 12253 | W5: 12503 | X5: 12853 | Y5: 172435 | Z5: East India | AA5: =(MAX(B5:X5)-B5)/B5 -> 3.8246997
A6: Chhattisgarh | B6: 795 | C6: 804 | D6: 812 | E6: 831 | F6: 839 | G6: 849 | H6: 866 | I6: 908 | J6: 956 | K6: 1029 | L6: 1119 | M6: 1164 | N6: 1209 | O6: 1232 | P6: 1277 | Q6: 1374 | R6: 1469 | S6: 1567 | T6: 1676 | U6: 1747 | V6: 1848 | W6: 1956 | X6: 2124 | Y6: 28451 | Z6: Central India | AA6: =(MAX(B6:X6)-B6)/B6 -> 1.6716981
A7: Goa | B7: 45 | C7: 46 | D7: 48 | E7: 57 | F7: 56 | G7: 57 | H7: 58 | I7: 59 | J7: 59 | K7: 60 | L7: 60 | M7: 61 | N7: 68 | O7: 67 | P7: 54 | Q7: 51 | R7: 55 | S7: 57 | T7: 61 | U7: 60 | V7: 63 | W7: 64 | X7: 64 | Y7: 1330 | Z7: West India | AA7: =(MAX(B7:X7)-B7)/B7 -> 0.51111111
A8: Gujarat | B8: 5862 | C8: 6089 | D8: 6421 | E8: 6745 | F8: 6960 | G8: 7533 | H8: 7911 | I8: 8386 | J8: 8844 | K8: 9321 | L8: 9817 | M8: 10315 | N8: 11112 | O8: 11691 | P8: 12262 | Q8: 12784 | R8: 13569 | S8: 14493 | T8: 15292 | U8: 15853 | V8: 16722 | W8: 17281 | X8: 18312 | Y8: 253575 | Z8: West India | AA8: =(MAX(B8:X8)-B8)/B8 -> 2.1238485
A9: Haryana | B9: 4978 | C9: 5124 | D9: 5221 | E9: 5222 | F9: 5299 | G9: 5366 | H9: 5442 | I9: 5745 | J9: 6006 | K9: 6267 | L9: 6661 | M9: 7040 | N9: 7442 | O9: 7901 | P9: 8381 | Q9: 8975 | R9: 9809 | S9: 10726 | T9: 11735 | U9: 11284 | V9: 11630 | W9: 11966 | X9: 12220 | Y9: 180440 | Z9: North India | AA9: =(MAX(B9:X9)-B9)/B9 -> 1.4548011
A10: Himachal Pradesh | B10: 756 | C10: 773 | D10: 786 | E10: 870 | F10: 869 | G10: 933 | H10: 1007 | I10: 1026 | J10: 971 | K10: 1102 | L10: 1120 | M10: 1139 | N10: 1151 | O10: 1172 | P10: 1283 | Q10: 1329 | R10: 1392 | S10: 1460 | T10: 1531 | U10: 1576 | V10: 1615 | W10: 1617 | X10: 1749 | Y10: 27227 | Z10: North India | AA10: =(MAX(B10:X10)-B10)/B10 -> 1.3134921
A11: J & K | B11: 1360 | C11: 1389 | D11: 1414 | E11: 1422 | F11: 1400 | G11: 1400 | H11: 1519 | I11: 1565 | J11: 1592 | K11: 1609 | L11: 1614 | M11: 1631 | N11: 1615 | O11: 1951 | P11: 2273 | Q11: 2376 | R11: 2460 | S11: 2540 | T11: 2506 | U11: 2595 | V11: 2727 | W11: 2817 | X11: 2875 | Y11: 44650 | Z11: North India | AA11: =(MAX(B11:X11)-B11)/B11 -> 1.1139706
A12: Jharkhand | B12: 940 | C12: 952 | D12: 954 | E12: 1330 | F12: 1335 | G12: 1401 | H12: 1442 | I12: 1466 | J12: 1463 | K12: 1555 | L12: 1745 | M12: 1679 | N12: 1700 | O12: 1734 | P12: 1812 | Q12: 1894 | R12: 2016 | S12: 2183 | T12: 2321 | U12: 2434 | V12: 2629 | W12: 2774 | X12: 3025 | Y12: 40784 | Z12: East India | AA12: =(MAX(B12:X12)-B12)/B12 -> 2.2180851
A13: Karnataka | B13: 4797 | C13: 4539 | D13: 3857 | E13: 3917 | F13: 4022 | G13: 4124 | H13: 4244 | I13: 4538 | J13: 4822 | K13: 5114 | L13: 5447 | M13: 5718 | N13: 5997 | O13: 6121 | P13: 6344 | Q13: 6562 | R13: 7137 | S13: 7901 | T13: 9031 | U13: 10936 | V13: 11796 | W13: 12829 | X13: 13463 | Y13: 153256 | Z13: South India | AA13: =(MAX(B13:X13)-B13)/B13 -> 1.8065458
... A25: Tamil Nadu | B25: 4988 | C25: 4622 | D25: 4752 | E25: 4784 | F25: 5474 | G25: 6277 | H25: 6540 | I25: 6651 | J25: 6787 | K25: 6831 | L25: 6968 | M25: 7005 | N25: 7049 | O25: 7132 | P25: 7244 | Q25: 7556 | R25: 7742 | S25: 8362 | T25: 8759 | U25: 9790 | V25: 10107 | W25: 10317 | X25: 10808 | Y25: 166545 | Z25: South India | AA25: =(MAX(B25:X25)-B25)/B25 -> 1.1668003
A26: Telangana | B26: 0 | C26: 0 | D26: 0 | E26: 0 | F26: 0 | G26: 0 | H26: 0 | I26: 0 | J26: 0 | K26: 0 | L26: 0 | M26: 0 | N26: 0 | O26: 4207 | P26: 4442 | Q26: 4681 | R26: 4965 | S26: 5416 | T26: 5590 | U26: 5765 | V26: 5808 | W26: 5855 | X26: 5840 | Y26: 52569 | Z26: South India | AA26: =(MAX(B26:X26)-B26)/O26 -> 1.3917281
A27: Tripura | B27: 90 | C27: 79 | D27: 84 | E27: 86 | F27: 87 | G27: 89 | H27: 91 | I27: 96 | J27: 100 | K27: 104 | L27: 111 | M27: 118 | N27: 130 | O27: 141 | P27: 152 | Q27: 160 | R27: 174 | S27: 185 | T27: 199 | U27: 206 | V27: 217 | W27: 230 | X27: 247 | Y27: 3176 | Z27: North-East India | AA27: =(MAX(B27:X27)-B27)/B27 -> 1.7444444
A28: Uttar Pradesh | B28: 14648 | C28: 15288 | D28: 15943 | E28: 16512 | F28: 17356 | G28: 18094 | H28: 18861 | I28: 19537 | J28: 20203 | K28: 21031 | L28: 22556 | M28: 23330 | N28: 24194 | O28: 25198 | P28: 26387 | Q28: 27770 | R28: 29052 | S28: 30519 | T28: 31864 | U28: 31359 | V28: 33874 | W28: 36242 | X28: 38780 | Y28: 558598 | Z28: North India | AA28: =(MAX(B28:X28)-B28)/B28 -> 1.6474604
A29: Uttarakhand | B29: 1066 | C29: 1079 | D29: 1188 | E29: 1195 | F29: 1206 | G29: 1213 | H29: 1221 | I29: 1230 | J29: 1377 | K29: 1383 | L29: 1417 | M29: 1478 | N29: 1550 | O29: 1565 | P29: 1656 | Q29: 1692 | R29: 1742 | S29: 1792 | T29: 1845 | U29: 1797 | V29: 1856 | W29: 1859 | X29: 1898 | Y29: 34305 | Z29: North India | AA29: =(MAX(B29:X29)-B29)/B29 -> 0.7804878
A30: West Bengal | B30: 3515 | C30: 3600 | D30: 3686 | E30: 3790 | F30: 3891 | G30: 3983 | H30: 4087 | I30: 4176 | J30: 4300 | K30: 4471 | L30: 4672 | M30: 4859 | N30: 4906 | O30: 4961 | P30: 5038 | Q30: 5183 | R30: 5389 | S30: 5607 | T30: 5869 | U30: 6165 | V30: 6414 | W30: 6969 | X30: 7650 | Y30: 113181 | Z30: East India | AA30: =(MAX(B30:X30)-B30)/B30 -> 1.1763869
A31: A&N Islands | B31: 23 | C31: 26 | D31: 25 | E31: 24 | F31: 20 | G31: 23 | H31: 24 | I31: 26 | J31: 24 | K31: 25 | L31: 26 | M31: 21 | N31: 14 | O31: 16 | P31: 15 | Q31: 16 | R31: 17 | S31: 18 | T31: 19 | U31: 15 | V31: 17 | W31: 17 | X31: 18 | Y31: 469 | Z31: Island Territories | AA31: =(MAX(B31:X31)-B31)/B31 -> 0.13043478
A32: Chandigarh | B32: 43 | C32: 43 | D32: 44 | E32: 43 | F32: 46 | G32: 46 | H32: 47 | I32: 47 | J32: 46 | K32: 45 | L32: 45 | M32: 44 | N32: 44 | O32: 44 | P32: 43 | Q32: 36 | R32: 42 | S32: 45 | T32: 49 | U32: 52 | V32: 57 | W32: 56 | X32: 58.87 | Y32: 1007 | Z32: North India | AA32: =(MAX(B32:X32)-B32)/B32 -> 0.3255814
A33: Ladakh | B33: 0 | C33: 0 | D33: 0 | E33: 0 | F33: 0 | G33: 0 | H33: 0 | I33: 0 | J33: 0 | K33: 0 | L33: 0 | M33: 0 | N33: 0 | O33: 0 | P33: 0 | Q33: 0 | R33: 0 | S33: 0 | T33: 0 | U33: 15 | V33: 29 | W33: 31 | X33: 29.31 | Y33: 104.31 | Z33: North India | AA33: =(MAX(B33:X33)-B33)/U33 -> 2.0666667
A34: D&N Haveli | B34: 8 | C34: 8 | D34: 8 | E34: 4 | F34: 5 | G34: 5 | H34: 10 | I34: 10 | J34: 10 | K34: 11 | L34: 11 | M34: 11 | N34: 11 | O34: 9 | P34: 9 | Q34: 8 | R34: 8 | S34: 1 | T34: 1 | U34: 1 | V34: 2 | W34: 2 | X34: 2 | Y34: 155 | Z34: West India | AA34: =(MAX(B34:X34)-B34)/B34 -> 0.375
A35: Daman & Diu | B35: 1 | C35: 1 | D35: 1 | E35: 1 | F35: 1 | G35: 1 | H35: 1 | I35: 1 | J35: 1 | K35: 1 | L35: 1 | M35: 1 | N35: 1 | O35: 1 | P35: 0 | Q35: 0 | R35: 0 | S35: 0 | T35: 0 | U35: 0 | V35: 0 | W35: 0 | X35: 0 | Y35: 14 | Z35: West India | AA35: =(MAX(B35:X35)-B35)/B35 -> 0
A36: Delhi | B36: 294 | C36: 296 | D36: 299 | E36: 303 | F36: 310 | G36: 288 | H36: 445 | I36: 450 | J36: 466 | K36: 480 | L36: 502 | M36: 287 | N36: 284 | O36: 280 | P36: 281 | Q36: 279 | R36: 279 | S36: 300 | T36: 300 | U36: 450 | V36: 450 | W36: 488 | X36: 488 | Y36: 8299 | Z36: North India | AA36: =(MAX(B36:X36)-B36)/B36 -> 0.70748299
A37: Lakshadweep | B37: 2 | C37: 2 | D37: 1 | E37: 1 | F37: 2 | G37: 2 | H37: 2 | I37: 2 | J37: 2 | K37: 2 | L37: 2 | M37: 2 | N37: 6 | O37: 4 | P37: 3 | Q37: 3 | R37: 3 | S37: 4 | T37: 4 | U37: 4 | V37: 0.42 | W37: 0.41 | X37: 0.39 | Y37: 54.22 | Z37: Island Territories | AA37: =(MAX(B37:X37)-B37)/B37 -> 2
A38: Puducherry | B38: 37 | C38: 37 | D38: 40 | E38: 41 | F38: 43 | G38: 45 | H38: 46 | I38: 46 | J38: 46 | K38: 47 | L38: 45 | M38: 47 | N38: 47 | O38: 48 | P38: 48 | Q38: 48 | R38: 49 | S38: 49 | T38: 50 | U38: 50 | V38: 50 | W38: 50 | X38: 50 | Y38: 1059 | Z38: South India | AA38: =(MAX(B38:X38)-B38)/B38 -> 0.35135135
A39: All India | B39: 84406 | C39: 86159 | D39: 88082 | E39: 92484 | F39: 97066 | G39: 102580 | H39: 107934 | I39: 112183 | J39: 116425 | K39: 121848 | L39: 127904 | M39: 132431 | N39: 137685 | O39: 146314 | P39: 155491 | Q39: 165404 | R39: 176347 | S39: 187749 | T39: 198440 | U39: 209960 | V39: 222069 | W39: 230577 | X39: 239299 | Y39: 3338837 | AA39: =(MAX(B39:X39)-B39)/B39 -> 1.8350947
A43: 2001- 02 | B43: 2002- 03 | C43: 2003- 04 | D43: 2004- 05 | E43: 2005- 06 | F43: 2006- 07 | G43: 2007- 08 | H43: 2008- 09 | I43: 2009- 10 | J43: 2010- 11 | K43: 2011- 12 | L43: 2012- 13 | M43: 2013- 14 | N43: 2014- 15 | O43: 2015- 16 | P43: 2016- 17 | Q43: 2017-18 | R43: 2018-19 | S43: 2019-20 | T43: 2020-21 | U43: 2021-22 | V43: 2022- 23 | W43: 2023- 24
A44: 84406 | B44: 86159 | C44: 88082 | D44: 92484 | E44: 97066 | F44: 102580 | G44: 107934 | H44: 112183 | I44: 116425 | J44: 121848 | K44: 127904 | L44: 132431 | M44: 137685 | N44: 146314 | O44: 155491 | P44: 165404 | Q44: 176347 | R44: 187749 | S44: 198440 | T44: 209960 | U44: 222069 | V44: 230577 | W44: 239299

Sheet Table 1
A1: State | B1: 2001- 02 | C1: 2002- 03 | D1: 2003- 04 | E1: 2004- 05 | F1: 2005- 06 | G1: 2006- 07 | H1: 2007- 08 | I1: 2008- 09 | J1: 2009- 10 | K1: 2010- 11 | L1: 2011- 12 | M1: 2012- 13 | N1: 2013- 14 | O1: 2014- 15 | P1: 2015- 16 | Q1: 2016- 17 | R1: 2017-18 | S1: 2018-19 | T1: 2019-20 | U1: 2020-21 | V1: 2021-22 | W1: 2022- 23 | X1: 2023- 24 | Y1: Total | Z1: Region
A2: All India | B2: 84406 | C2: 86159 | D2: 88082 | E2: 92484 | F2: 97066 | G2: 102580 | H2: 107934 | I2: 112183 | J2: 116425 | K2: 121848 | L2: 127904 | M2: 132431 | N2: 137685 | O2: 146314 | P2: 155491 | Q2: 165404 | R2: 176347 | S2: 187749 | T2: 198440 | U2: 209960 | V2: 222069 | W2: 230577 | X2: 239299 | Y2: =SUM(Table1[[#This Row],[2001- 02]:[2023- 24]]) -> 3338837
A3: Andhra Pradesh | B3: 5814 | C3: 6584 | D3: 6959 | E3: 7257 | F3: 7624 | G3: 7938 | H3: 8925 | I3: 9570 | J3: 10429 | K3: 11203 | L3: 12088 | M3: 12762 | N3: 13007 | O3: 9656 | P3: 10817 | Q3: 12178 | R3: 13725 | S3: 15044 | T3: 15263 | U3: 14714 | V3: 15403 | W3: 15448 | X3: 13994 | Y3: =SUM(Table1[[#This Row],[2001- 02]:[2023- 24]]) -> 256402 | Z3: South India
A4: Arunachal Pradesh | B4: 42 | C4: 46 | D4: 46 | E4: 48 | F4: 48 | G4: 49 | H4: 32 | I4: 24 | J4: 26 | K4: 28 | L4: 22 | M4: 23 | N4: 43 | O4: 46 | P4: 50 | Q4: 53 | R4: 54 | S4: 55 | T4: 61 | U4: 44 | V4: 46 | W4: 46 | X4: 20 | Y4: =SUM(Table1[[#This Row],[2001- 02]:[2023- 24]]) -> 952 | Z4: North-East India
A5: Assam | B5: 682 | C5: 705 | D5: 727 | E5: 739 | F5: 747 | G5: 750 | H5: 752 | I5: 753 | J5: 756 | K5: 790 | L5: 796 | M5: 800 | N5: 815 | O5: 829 | P5: 843 | Q5: 861 | R5: 872 | S5: 882 | T5: 920 | U5: 954 | V5: 982 | W5: 1006 | X5: 1092 | Y5: =SUM(Table1[[#This Row],[2001- 02]:[2023- 24]]) -> 19053 | Z5: North-East India
A6: Bihar | B6: 2664 | C6: 2869 | D6: 3180 | E6: 4743 | F6: 5060 | G6: 5451 | H6: 5783 | I6: 5934 | J6: 6124 | K6: 6517 | L6: 6643 | M6: 6845 | N6: 7197 | O6: 7775 | P6: 8288 | Q6: 8711 | R6: 9242 | S6: 9818 | T6: 10480 | U6: 11502 | V6: 12253 | W6: 12503 | X6: 12853 | Y6: =SUM(Table1[[#This Row],[2001- 02]:[2023- 24]]) -> 172435 | Z6: East India
A7: Chhattisgarh | B7: 795 | C7: 804 | D7: 812 | E7: 831 | F7: 839 | G7: 849 | H7: 866 | I7: 908 | J7: 956 | K7: 1029 | L7: 1119 | M7: 1164 | N7: 1209 | O7: 1232 | P7: 1277 | Q7: 1374 | R7: 1469 | S7: 1567 | T7: 1676 | U7: 1747 | V7: 1848 | W7: 1956 | X7: 2124 | Y7: =SUM(Table1[[#This Row],[2001- 02]:[2023- 24]]) -> 28451 | Z7: Central India
A8: Goa | B8: 45 | C8: 46 | D8: 48 | E8: 57 | F8: 56 | G8: 57 | H8: 58 | I8: 59 | J8: 59 | K8: 60 | L8: 60 | M8: 61 | N8: 68 | O8: 67 | P8: 54 | Q8: 51 | R8: 55 | S8: 57 | T8: 61 | U8: 60 | V8: 63 | W8: 64 | X8: 64 | Y8: =SUM(Table1[[#This Row],[2001- 02]:[2023- 24]]) -> 1330 | Z8: West India
A9: Gujarat | B9: 5862 | C9: 6089 | D9: 6421 | E9: 6745 | F9: 6960 | G9: 7533 | H9: 7911 | I9: 8386 | J9: 8844 | K9: 9321 | L9: 9817 | M9: 10315 | N9: 11112 | O9: 11691 | P9: 12262 | Q9: 12784 | R9: 13569 | S9: 14493 | T9: 15292 | U9: 15853 | V9: 16722 | W9: 17281 | X9: 18312 | Y9: =SUM(Table1[[#This Row],[2001- 02]:[2023- 24]]) -> 253575 | Z9: West India
A10: Haryana | B10: 4978 | C10: 5124 | D10: 5221 | E10: 5222 | F10: 5299 | G10: 5366 | H10: 5442 | I10: 5745 | J10: 6006 | K10: 6267 | L10: 6661 | M10: 7040 | N10: 7442 | O10: 7901 | P10: 8381 | Q10: 8975 | R10: 9809 | S10: 10726 | T10: 11735 | U10: 11284 | V10: 11630 | W10: 11966 | X10: 12220 | Y10: =SUM(Table1[[#This Row],[2001- 02]:[2023- 24]]) -> 180440 | Z10: North India
A11: Himachal Pradesh | B11: 756 | C11: 773 | D11: 786 | E11: 870 | F11: 869 | G11: 933 | H11: 1007 | I11: 1026 | J11: 971 | K11: 1102 | L11: 1120 | M11: 1139 | N11: 1151 | O11: 1172 | P11: 1283 | Q11: 1329 | R11: 1392 | S11: 1460 | T11: 1531 | U11: 1576 | V11: 1615 | W11: 1617 | X11: 1749 | Y11: =SUM(Table1[[#This Row],[2001- 02]:[2023- 24]]) -> 27227 | Z11: North India
A12: J & K | B12: 1360 | C12: 1389 | D12: 1414 | E12: 1422 | F12: 1400 | G12: 1400 | H12: 1519 | I12: 1565 | J12: 1592 | K12: 1609 | L12: 1614 | M12: 1631 | N12: 1615 | O12: 1951 | P12: 2273 | Q12: 2376 | R12: 2460 | S12: 2540 | T12: 2506 | U12: 2595 | V12: 2727 | W12: 2817 | X12: 2875 | Y12: =SUM(Table1[[#This Row],[2001- 02]:[2023- 24]]) -> 44650 | Z12: North India
A13: Jharkhand | B13: 940 | C13: 952 | D13: 954 | E13: 1330 | F13: 1335 | G13: 1401 | H13: 1442 | I13: 1466 | J13: 1463 | K13: 1555 | L13: 1745 | M13: 1679 | N13: 1700 | O13: 1734 | P13: 1812 | Q13: 1894 | R13: 2016 | S13: 2183 | T13: 2321 | U13: 2434 | V13: 2629 | W13: 2774 | X13: 3025 | Y13: =SUM(Table1[[#This Row],[2001- 02]:[2023- 24]]) -> 40784 | Z13: East India
A14: Karnataka | B14: 4797 | C14: 4539 | D14: 3857 | E14: 3917 | F14: 4022 | G14: 4124 | H14: 4244 | I14: 4538 | J14: 4822 | K14: 5114 | L14: 5447 | M14: 5718 | N14: 5997 | O14: 6121 | P14: 6344 | Q14: 6562 | R14: 7137 | S14: 7901 | T14: 9031 | U14: 10936 | V14: 11796 | W14: 12829 | X14: 13463 | Y14: =SUM(Table1[[#This Row],[2001- 02]:[2023- 24]]) -> 153256 | Z14: South India
... A32: A&N Islands | B32: 23 | C32: 26 | D32: 25 | E32: 24 | F32: 20 | G32: 23 | H32: 24 | I32: 26 | J32: 24 | K32: 25 | L32: 26 | M32: 21 | N32: 14 | O32: 16 | P32: 15 | Q32: 16 | R32: 17 | S32: 18 | T32: 19 | U32: 15 | V32: 17 | W32: 17 | X32: 18 | Y32: =SUM(Table1[[#This Row],[2001- 02]:[2023- 24]]) -> 469 | Z32: Island Territories
A33: Chandigarh | B33: 43 | C33: 43 | D33: 44 | E33: 43 | F33: 46 | G33: 46 | H33: 47 | I33: 47 | J33: 46 | K33: 45 | L33: 45 | M33: 44 | N33: 44 | O33: 44 | P33: 43 | Q33: 36 | R33: 42 | S33: 45 | T33: 49 | U33: 52 | V33: 57 | W33: 56 | X33: 58.87 | Y33: =SUM(Table1[[#This Row],[2001- 02]:[2023- 24]]) -> 1007 | Z33: North India
A34: Ladakh | B34: 0 | C34: 0 | D34: 0 | E34: 0 | F34: 0 | G34: 0 | H34: 0 | I34: 0 | J34: 0 | K34: 0 | L34: 0 | M34: 0 | N34: 0 | O34: 0 | P34: 0 | Q34: 0 | R34: 0 | S34: 0 | T34: 0 | U34: 15 | V34: 29 | W34: 31 | X34: 29.31 | Y34: =SUM(Table1[[#This Row],[2001- 02]:[2023- 24]]) -> 104.31 | Z34: North India
A35: D&N Haveli | B35: 8 | C35: 8 | D35: 8 | E35: 4 | F35: 5 | G35: 5 | H35: 10 | I35: 10 | J35: 10 | K35: 11 | L35: 11 | M35: 11 | N35: 11 | O35: 9 | P35: 9 | Q35: 8 | R35: 8 | S35: 1 | T35: 1 | U35: 1 | V35: 2 | W35: 2 | X35: 2 | Y35: =SUM(Table1[[#This Row],[2001- 02]:[2023- 24]]) -> 155 | Z35: West India
A36: Daman & Diu | B36: 1 | C36: 1 | D36: 1 | E36: 1 | F36: 1 | G36: 1 | H36: 1 | I36: 1 | J36: 1 | K36: 1 | L36: 1 | M36: 1 | N36: 1 | O36: 1 | P36: 0 | Q36: 0 | R36: 0 | S36: 0 | T36: 0 | U36: 0 | V36: 0 | W36: 0 | X36: 0 | Y36: =SUM(Table1[[#This Row],[2001- 02]:[2023- 24]]) -> 14 | Z36: West India
A37: Delhi | B37: 294 | C37: 296 | D37: 299 | E37: 303 | F37: 310 | G37: 288 | H37: 445 | I37: 450 | J37: 466 | K37: 480 | L37: 502 | M37: 287 | N37: 284 | O37: 280 | P37: 281 | Q37: 279 | R37: 279 | S37: 300 | T37: 300 | U37: 450 | V37: 450 | W37: 488 | X37: 488 | Y37: =SUM(Table1[[#This Row],[2001- 02]:[2023- 24]]) -> 8299 | Z37: North India
A38: Lakshadweep | B38: 2 | C38: 2 | D38: 1 | E38: 1 | F38: 2 | G38: 2 | H38: 2 | I38: 2 | J38: 2 | K38: 2 | L38: 2 | M38: 2 | N38: 6 | O38: 4 | P38: 3 | Q38: 3 | R38: 3 | S38: 4 | T38: 4 | U38: 4 | V38: 0.42 | W38: 0.41 | X38: 0.39 | Y38: =SUM(Table1[[#This Row],[2001- 02]:[2023- 24]]) -> 54.22 | Z38: Island Territories
A39: Puducherry | B39: 37 | C39: 37 | D39: 40 | E39: 41 | F39: 43 | G39: 45 | H39: 46 | I39: 46 | J39: 46 | K39: 47 | L39: 45 | M39: 47 | N39: 47 | O39: 48 | P39: 48 | Q39: 48 | R39: 49 | S39: 49 | T39: 50 | U39: 50 | V39: 50 | W39: 50 | X39: 50 | Y39: =SUM(Table1[[#This Row],[2001- 02]:[2023- 24]]) -> 1059 | Z39: South India

Sheet Dash
A2: Milk Production in India (2001-2024)
C6: Total Milk Production (Tonnes) | N6: States (Ranking) | S6: Insights
S7: Drop Down
C8: =GETPIVOTDATA("Milk",Sheet2!$S$3) -> 1567 | N8: =Sheet2!Z4 -> Uttar Pradesh | S8: Haryana
N9: =Sheet2!Z5 -> Madhya Pradesh
N10: =Sheet2!Z6 -> Andhra Pradesh | S10: =VLOOKUP($S$8,Sheet2!$AC$1:$AD$21,2,FALSE) -> Linear growth after 2020 due to covid, excpected to boom after 2024-2025
C11: Regions (Ranking) | N11: =Sheet2!Z7 -> Gujarat
C12: =Sheet2!V2 -> North India | N12: =Sheet2!Z8 -> Maharashtra
C13: =Sheet2!V3 -> South India | N13: =Sheet2!Z9 -> Haryana
C14: =Sheet2!V4 -> West India | N14: =Sheet2!Z10 -> Bihar
C15: =Sheet2!V5 -> East India | N15: =Sheet2!Z11 -> Punjab
C16: =Sheet2!V6 -> Central India | N16: =Sheet2!Z12 -> Telangana
C17: =Sheet2!V7 -> North East India | N17: =Sheet2!Z13 -> Karnataka
S19: State / Region Milk Production (Tonne)
S22: =GETPIVOTDATA("Milk",Sheet2!$AF$5) -> 1567

Sheet Sheet2
A1: Region | B1: North India | D1: Year | E1: (All) | G1: Region | H1: (All) | J1: Row Labels | K1: Sum of Total Increase | P1: Most Inrease In Milk Production | S1: Year | T1: 2018-19 | V1: Row Labels | W1: Sum of Milk | Z1: Year | AA1: 2018-19 | AC1: UP | AD1: Consistent No 1 since 2001 | AF1: Region | AG1: (All)
G2: State | H2: Chhattisgarh | J2: Bihar | K2: 3.8246997 | P2: Milk Prod Groth In India | V2: North India | W2: 55512 | AC2: MP | AD2: Emerged in last 10 years | Consistent Top 3 | High Volumes | AF2: Year | AG2: 2018-19
A3: Row Labels | B3: Sum of Milk | D3: Row Labels | E3: Sum of Milk | J3: Rajasthan | K3: 3.4770559 | M3: Year | N3: 2018-19 | P3: Region Wise Milk Poduction Currently | S3: Sum of Milk | V3: South India | W3: 41275 | Z3: Row Labels | AA3: Sum of Milk | AC3: Gujrat | AD3: Always been a high milk producing State | Consistent Top 4 since 2001 | AF3: State | AG3: Chhattisgarh
A4: Uttar Pradesh | B4: 464324 | D4: Uttar Pradesh | E4: 464324 | G4: Row Labels | H4: Sum of Milk | J4: Madhya Pradesh | K4: 3.0367216 | P4: Region Wise Top Milk Producers | S4: 1567 | V4: West India | W4: 26205 | Z4: Uttar Pradesh | AA4: 23146 | AC4: Maharashtra | AD4: Consistent Performer | Maintained 4th or 5th position through out
A5: Punjab | B5: 193993 | D5: Andhra Pradesh | E5: 256402 | G5: 2001-02 | H5: 795 | J5: Jharkhand | K5: 2.2180851 | M5: Row Labels | N5: Sum of Milk | P5: Total Milk Production In India Lastest | V5: East India | W5: 21810 | Z5: Madhya Pradesh | AA5: 15911 | AC5: Andhra Pradesh | AD5: Historically high milk producer | Dropped through ranks with rise of MP and consistency of Guj, MH | AF5: Sum of Milk
A6: Haryana | B6: 180440 | D6: Gujarat | E6: 253575 | G6: 2002-03 | H6: 804 | J6: Gujarat | K6: 2.1238485 | M6: Central India | N6: 17478 | P6: Region wise Milk Growth | V6: Central India | W6: 17478 | Z6: Andhra Pradesh | AA6: 15044 | AC6: Punjab | AD6: Consistently dropping through ranks | Stable growth | AF6: 1567
A7: Rajasthan | B7: 134320 | D7: Madhya Pradesh | E7: 251427 | G7: 2003-04 | H7: 812 | J7: Ladakh | K7: 2.0666667 | M7: Chhattisgarh | N7: 1567 | P7: Region wise Milk Production | V7: North East India | W7: 1488 | Z7: Gujarat | AA7: 14493 | AC7: Bihar & Rajathan | AD7: Grown most but still low vol as compared to Top 10
A8: Jammu Kashmir | B8: 44650 | D8: Maharashtra | E8: 219678 | G8: 2004-05 | H8: 831 | J8: Lakshadweep | K8: 2 | M8: Madhya Pradesh | N8: 15911 | V8: Grand Total | W8: 163768 | Z8: Maharashtra | AA8: 11655 | AC8: Central India | AD8: Boomed after 2012
A9: Grand Total | B9: 1017727 | D9: Punjab | E9: 193993 | G9: 2005-06 | H9: 839 | J9: Grand Total | K9: 18.747077 | M9: East India | N9: 21810 | V9: Region wise milk prod | Z9: Haryana | AA9: 10726 | AC9: North East | AD9: Stable growth | Nothing Extraordinary
A10: Region wise State wise Top Production | D10: Haryana | E10: 180440 | G10: 2006-07 | H10: 849 | J10: Most Increase In Production | M10: Bihar | N10: 9818 | Z10: Bihar | AA10: 9818 | AC10: West India | AD10: Consistent growth since 2008
A11: Top States inRegion | D11: Bihar | E11: 172435 | G11: 2007-08 | H11: 866 | J11: Highest Growth Rate | M11: Jharkhand | N11: 2183 | Z11: Punjab | AA11: 8762 | AC11: South India | AD11: Consistent Growth through out
D12: Telangana | E12: 162971 | G12: 2008-09 | H12: 908 | M12: Odisha | N12: 2311 | Z12: Telangana | AA12: 8592 | AC12: Haryana | AD12: Linear growth after 2020 due to covid, excpected to boom after 2024-2025
D13: Karnataka | E13: 153256 | G13: 2009-10 | H13: 956 | M13: West Bengal | N13: 7498 | Z13: Karnataka | AA13: 7901 | AC13: Big Fish (Central India) | AD13: MP alone produces 90% of Milk from Central India
D14: Grand Total | E14: 2308501 | G14: 2010-11 | H14: 1029 | M14: North East India | N14: 1488 | Z14: Grand Total | AA14: 126048 | AC14: Big Fish (East India) | AD14: Bihar(48%) & WB(31%) alone produces 79% from East India Region
D15: State Wise yearwise Top | G15: 2011-12 | H15: 1119 | M15: Arunanchal Pradesh | N15: 55 | Z15: States Ranking | AC15: Big Fish (North East India) | AD15: Assam alone produces 67% from this region followed by Tripura(16%)
D16: Top Producer States | G16: 2012-13 | H16: 1164 | M16: Assam | N16: 882 | AC16: Big Fish (North India) | AD16: UP(50%)+HR(20%)+PB(14%) together produces 77% of North India's Milk followed by RAJ (11.5%)
G17: 2013-14 | H17: 1209 | M17: Manipur | N17: 86 | AC17: Big Fish (South India) | AD17: Andhra(29%) + Karnataka(28%) + Telangana(21%) together produces 78% milk from this region
G18: 2014-15 | H18: 1232 | M18: Meghalaya | N18: 87 | AC18: Big Fish(West India) | AD18: Guj(53%) + Mah(46%) together produces 99% milk from this region
G19: 2015-16 | H19: 1277 | M19: Mizoram | N19: 26 | AC19: Big Fish 1(India) | AD19: UP(13%) MP(10%) GUJ(9%) MAH(8%) Andhra P(7%) together produced 48.8% of India's Milk
G20: 2016-17 | H20: 1374 | M20: Nagaland | N20: 73 | AC20: Big Fish 2(India) | AD20: North India(31.30%) South India(24%) together produces 55.3% of India's Milk
G21: 2017-18 | H21: 1469 | M21: Sikkim | N21: 31 | AC21: Big Fish India 3(India) | AD21: North(31%) South(24%) West(17%) Central(12%) East(14%) North East(0.01%)
G22: 2018-19 | H22: 1567 | M22: Tripura | N22: 248
G23: 2019-20 | H23: 1676 | M23: North India | N23: 55512
G24: 2020-21 | H24: 1747 | M24: Delhi | N24: 665
G25: 2021-22 | H25: 1848 | M25: Haryana | N25: 10726
G26: 2022-23 | H26: 1956 | M26: Himachal Pradesh | N26: 1460
G27: 2023-24 | H27: 2124 | M27: Jammu Kashmir | N27: 2540
G28: Grand Total | H28: 28451 | M28: Punjab | N28: 8762
G29: Line Chart Region Wise / State Wise | M29: Rajasthan | N29: 6488
G30: Milk Production Progress | M30: Uttar Pradesh | N30: 23146
M31: Uttarakhand | N31: 1725
M32: South India | N32: 41275
M33: Andhra Pradesh | N33: 15044
M34: Karnataka | N34: 7901
M35: Kerala | N35: 2548
M36: Tamil Nadu | N36: 7190
M37: Telangana | N37: 8592
M38: West India | N38: 26205
M39: Goa | N39: 57
M40: Gujarat | N40: 14493
...

Sheet Sheet4
A1: Year | B1: Region | C1: Milk
A2: 2001- 02 | B2: Central India | C2: 27534
A3: 2002- 03 | B3: Central India | C3: 27478
A4: 2003- 04 | B4: Central India | C4: 27012
A5: 2004- 05 | B5: Central India | C5: 27925
A6: 2005- 06 | B6: Central India | C6: 29126
A7: 2006- 07 | B7: Central India | C7: 30156
A8: 2007- 08 | B8: Central India | C8: 31314
A9: 2008- 09 | B9: Central India | C9: 32989
A10: 2009- 10 | B10: Central India | C10: 34389
A11: 2010- 11 | B11: Central India | C11: 36216
A12: 2011- 12 | B12: Central India | C12: 38448
A13: 2012- 13 | B13: Central India | C13: 40376
... A162: 2023- 24 | B162: West India | C162: 208619.31

Sheet Sheet6
A1: Year | B1: State | C1: Region | D1: Milk
A2: 2001-02 | B2: Andhra Pradesh | C2: South India | D2: 5814
A3: 2002-03 | B3: Andhra Pradesh | C3: South India | D3: 6584
A4: 2003-04 | B4: Andhra Pradesh | C4: South India | D4: 6959
A5: 2004-05 | B5: Andhra Pradesh | C5: South India | D5: 7257
A6: 2005-06 | B6: Andhra Pradesh | C6: South India | D6: 7624
A7: 2006-07 | B7: Andhra Pradesh | C7: South India | D7: 7938
A8: 2007-08 | B8: Andhra Pradesh | C8: South India | D8: 8925
A9: 2008-09 | B9: Andhra Pradesh | C9: South India | D9: 9570
A10: 2009-10 | B10: Andhra Pradesh | C10: South India | D10: 10429
A11: 2010-11 | B11: Andhra Pradesh | C11: South India | D11: 11203
A12: 2011-12 | B12: Andhra Pradesh | C12: South India | D12: 12088
A13: 2012-13 | B13: Andhra Pradesh | C13: South India | D13: 12762
... A689: 2023-24 | B689: Delhi | C689: North India | D689: 735
